Traceback (most recent call last):
  File "/Users/skojaku-admin/miniforge3/envs/advnetsci/lib/python3.11/site-packages/jupyter_cache/executors/utils.py", line 58, in single_nb_execution
    executenb(
  File "/Users/skojaku-admin/miniforge3/envs/advnetsci/lib/python3.11/site-packages/nbclient/client.py", line 1305, in execute
    return NotebookClient(nb=nb, resources=resources, km=km, **kwargs).execute()
           ^^^^^^^^^^^^^^^^^^^^^^^^^^^^^^^^^^^^^^^^^^^^^^^^^^^^^^^^^^^^^^^^^^^^^
  File "/Users/skojaku-admin/miniforge3/envs/advnetsci/lib/python3.11/site-packages/jupyter_core/utils/__init__.py", line 165, in wrapped
    return loop.run_until_complete(inner)
           ^^^^^^^^^^^^^^^^^^^^^^^^^^^^^^
  File "/Users/skojaku-admin/miniforge3/envs/advnetsci/lib/python3.11/asyncio/base_events.py", line 650, in run_until_complete
    return future.result()
           ^^^^^^^^^^^^^^^
  File "/Users/skojaku-admin/miniforge3/envs/advnetsci/lib/python3.11/contextlib.py", line 222, in __aexit__
    await self.gen.athrow(typ, value, traceback)
  File "/Users/skojaku-admin/miniforge3/envs/advnetsci/lib/python3.11/site-packages/nbclient/client.py", line 650, in async_setup_kernel
    yield
  File "/Users/skojaku-admin/miniforge3/envs/advnetsci/lib/python3.11/site-packages/nbclient/client.py", line 705, in async_execute
    await self.async_execute_cell(
  File "/Users/skojaku-admin/miniforge3/envs/advnetsci/lib/python3.11/site-packages/nbclient/client.py", line 1058, in async_execute_cell
    await self._check_raise_for_error(cell, cell_index, exec_reply)
  File "/Users/skojaku-admin/miniforge3/envs/advnetsci/lib/python3.11/site-packages/nbclient/client.py", line 914, in _check_raise_for_error
    raise CellExecutionError.from_cell_and_msg(cell, exec_reply_content)
nbclient.exceptions.CellExecutionError: An error occurred while executing the following cell:
------------------
import numpy as np
import igraph

g = igraph.Graph()

g.add_vertices([0, 1, 2, 3, 4])
g.add_edges([(0, 1), (0, 2), (0, 3), (1, 3), (2, 3), (2, 4), (3, 4)])
igraph.draw(g, vertex_size=20, vertex_label=g.vs["name"])
------------------


[0;31m---------------------------------------------------------------------------[0m
[0;31mAttributeError[0m                            Traceback (most recent call last)
Cell [0;32mIn[1], line 8[0m
[1;32m      6[0m g[38;5;241m.[39madd_vertices([[38;5;241m0[39m, [38;5;241m1[39m, [38;5;241m2[39m, [38;5;241m3[39m, [38;5;241m4[39m])
[1;32m      7[0m g[38;5;241m.[39madd_edges([([38;5;241m0[39m, [38;5;241m1[39m), ([38;5;241m0[39m, [38;5;241m2[39m), ([38;5;241m0[39m, [38;5;241m3[39m), ([38;5;241m1[39m, [38;5;241m3[39m), ([38;5;241m2[39m, [38;5;241m3[39m), ([38;5;241m2[39m, [38;5;241m4[39m), ([38;5;241m3[39m, [38;5;241m4[39m)])
[0;32m----> 8[0m igraph[38;5;241m.[39mdraw(g, vertex_size[38;5;241m=[39m[38;5;241m20[39m, vertex_label[38;5;241m=[39mg[38;5;241m.[39mvs[[38;5;124m"[39m[38;5;124mname[39m[38;5;124m"[39m])

[0;31mAttributeError[0m: module 'igraph' has no attribute 'draw'

