Traceback (most recent call last):
  File "/Users/skojaku-admin/miniforge3/envs/advnetsci/lib/python3.11/site-packages/jupyter_cache/executors/utils.py", line 58, in single_nb_execution
    executenb(
  File "/Users/skojaku-admin/miniforge3/envs/advnetsci/lib/python3.11/site-packages/nbclient/client.py", line 1305, in execute
    return NotebookClient(nb=nb, resources=resources, km=km, **kwargs).execute()
           ^^^^^^^^^^^^^^^^^^^^^^^^^^^^^^^^^^^^^^^^^^^^^^^^^^^^^^^^^^^^^^^^^^^^^
  File "/Users/skojaku-admin/miniforge3/envs/advnetsci/lib/python3.11/site-packages/jupyter_core/utils/__init__.py", line 165, in wrapped
    return loop.run_until_complete(inner)
           ^^^^^^^^^^^^^^^^^^^^^^^^^^^^^^
  File "/Users/skojaku-admin/miniforge3/envs/advnetsci/lib/python3.11/asyncio/base_events.py", line 650, in run_until_complete
    return future.result()
           ^^^^^^^^^^^^^^^
  File "/Users/skojaku-admin/miniforge3/envs/advnetsci/lib/python3.11/contextlib.py", line 222, in __aexit__
    await self.gen.athrow(typ, value, traceback)
  File "/Users/skojaku-admin/miniforge3/envs/advnetsci/lib/python3.11/site-packages/nbclient/client.py", line 650, in async_setup_kernel
    yield
  File "/Users/skojaku-admin/miniforge3/envs/advnetsci/lib/python3.11/site-packages/nbclient/client.py", line 705, in async_execute
    await self.async_execute_cell(
  File "/Users/skojaku-admin/miniforge3/envs/advnetsci/lib/python3.11/site-packages/nbclient/client.py", line 1058, in async_execute_cell
    await self._check_raise_for_error(cell, cell_index, exec_reply)
  File "/Users/skojaku-admin/miniforge3/envs/advnetsci/lib/python3.11/site-packages/nbclient/client.py", line 914, in _check_raise_for_error
    raise CellExecutionError.from_cell_and_msg(cell, exec_reply_content)
nbclient.exceptions.CellExecutionError: An error occurred while executing the following cell:
------------------
import igraph
import matplotlib.pyplot as plt
import numpy as np

def visualize_graph(A, **params):
  A = np.array(A)
  src, trg = np.where(A)
  g = igraph.Graph(directed=False)
  g.add_vertices(A.shape[0])
  for s, t in zip(src, trg):
    for _ in range(A[s, t]):
      g.add_edge(s, t)
  return igraph.plot(g, **params)

visualize_graph(A)
------------------

----- stderr -----
/var/folders/j7/9dgqq5g53vnbsbmvh2yqtckr0000gr/T/ipykernel_19914/520002670.py:7: DeprecationWarning: Calling nonzero on 0d arrays is deprecated, as it behaves surprisingly. Use `atleast_1d(arr).nonzero()` if the old behavior was intended.
  src, trg = np.where(A)
------------------

[0;31m---------------------------------------------------------------------------[0m
[0;31mValueError[0m                                Traceback (most recent call last)
Cell [0;32mIn[4], line 15[0m
[1;32m     12[0m       g[38;5;241m.[39madd_edge(s, t)
[1;32m     13[0m   [38;5;28;01mreturn[39;00m igraph[38;5;241m.[39mplot(g, [38;5;241m*[39m[38;5;241m*[39mparams)
[0;32m---> 15[0m visualize_graph(A)

Cell [0;32mIn[4], line 7[0m, in [0;36mvisualize_graph[0;34m(A, **params)[0m
[1;32m      5[0m [38;5;28;01mdef[39;00m [38;5;21mvisualize_graph[39m(A, [38;5;241m*[39m[38;5;241m*[39mparams):
[1;32m      6[0m   A [38;5;241m=[39m np[38;5;241m.[39marray(A)
[0;32m----> 7[0m   src, trg [38;5;241m=[39m np[38;5;241m.[39mwhere(A)
[1;32m      8[0m   g [38;5;241m=[39m igraph[38;5;241m.[39mGraph(directed[38;5;241m=[39m[38;5;28;01mFalse[39;00m)
[1;32m      9[0m   g[38;5;241m.[39madd_vertices(A[38;5;241m.[39mshape[[38;5;241m0[39m])

[0;31mValueError[0m: not enough values to unpack (expected 2, got 1)

