Traceback (most recent call last):
  File "/Users/skojaku-admin/miniforge3/envs/advnetsci/lib/python3.11/site-packages/jupyter_cache/executors/utils.py", line 58, in single_nb_execution
    executenb(
  File "/Users/skojaku-admin/miniforge3/envs/advnetsci/lib/python3.11/site-packages/nbclient/client.py", line 1305, in execute
    return NotebookClient(nb=nb, resources=resources, km=km, **kwargs).execute()
           ^^^^^^^^^^^^^^^^^^^^^^^^^^^^^^^^^^^^^^^^^^^^^^^^^^^^^^^^^^^^^^^^^^^^^
  File "/Users/skojaku-admin/miniforge3/envs/advnetsci/lib/python3.11/site-packages/jupyter_core/utils/__init__.py", line 165, in wrapped
    return loop.run_until_complete(inner)
           ^^^^^^^^^^^^^^^^^^^^^^^^^^^^^^
  File "/Users/skojaku-admin/miniforge3/envs/advnetsci/lib/python3.11/asyncio/base_events.py", line 650, in run_until_complete
    return future.result()
           ^^^^^^^^^^^^^^^
  File "/Users/skojaku-admin/miniforge3/envs/advnetsci/lib/python3.11/contextlib.py", line 222, in __aexit__
    await self.gen.athrow(typ, value, traceback)
  File "/Users/skojaku-admin/miniforge3/envs/advnetsci/lib/python3.11/site-packages/nbclient/client.py", line 650, in async_setup_kernel
    yield
  File "/Users/skojaku-admin/miniforge3/envs/advnetsci/lib/python3.11/site-packages/nbclient/client.py", line 705, in async_execute
    await self.async_execute_cell(
  File "/Users/skojaku-admin/miniforge3/envs/advnetsci/lib/python3.11/site-packages/nbclient/client.py", line 1058, in async_execute_cell
    await self._check_raise_for_error(cell, cell_index, exec_reply)
  File "/Users/skojaku-admin/miniforge3/envs/advnetsci/lib/python3.11/site-packages/nbclient/client.py", line 914, in _check_raise_for_error
    raise CellExecutionError.from_cell_and_msg(cell, exec_reply_content)
nbclient.exceptions.CellExecutionError: An error occurred while executing the following cell:
------------------
import seaborn as sns
import matplotlib.pyplot as plt


ax = sns.lineplot(x=np.arange(len(ccdf_deg)), y=ccdf_deg, label='Node')
ax = sns.lineplot(x=np.arange(len(ccdf_deg)), y=ccdf_deg_friend, label='Friend', ax = ax)
ax.set_xscale('log')
ax.set_yscale('log')
ax.set_xlabel('Degree')
ax.set_ylabel('CCDF')
ax.legend(frameon = false)
------------------


[0;31m---------------------------------------------------------------------------[0m
[0;31mNameError[0m                                 Traceback (most recent call last)
Cell [0;32mIn[6], line 11[0m
[1;32m      9[0m ax[38;5;241m.[39mset_xlabel([38;5;124m'[39m[38;5;124mDegree[39m[38;5;124m'[39m)
[1;32m     10[0m ax[38;5;241m.[39mset_ylabel([38;5;124m'[39m[38;5;124mCCDF[39m[38;5;124m'[39m)
[0;32m---> 11[0m ax[38;5;241m.[39mlegend(frameon [38;5;241m=[39m false)

[0;31mNameError[0m: name 'false' is not defined

